<?xml version="1.0" ?>
<!-- =================================================================================== -->
<!-- |    This document was autogenerated by xacro from robot.xacro                    | -->
<!-- |    EDITING THIS FILE BY HAND IS NOT RECOMMENDED                                 | -->
<!-- =================================================================================== -->
<robot name="differential_drive_robot">
  <!-- Links -->
  <!-- Body Link -->
  <link name="body_link">
    <visual>
      <origin rpy="0.0 0.0 0.0" xyz="0.0 0.0 0.0"/>
      <geometry>
        <box size="0.5 0.3 0.1"/>
      </geometry>
      <material name="body_material">
        <color rgba="0.25 0.25 0.25 1.0"/>
      </material>
    </visual>
    <collision>
      <origin rpy="0.0 0.0 0.0" xyz="0.0 0.0 0.0"/>
      <geometry>
        <box size="0.5 0.3 0.1"/>
      </geometry>
    </collision>
    <inertial>
      <mass value="10"/>
      <inertia ixx="0.9812500000000001" ixy="0.0" ixz="0.0" iyy="2.55125" iyz="0" izz="3.3362499999999997"/>
      <origin rpy="0 0 0" xyz="0 0 0"/>
    </inertial>
  </link>
  <!-- Left Wheel -->
  <link name="left_wheel_link">
    <visual>
      <origin rpy="1.570795 0.0 0.0" xyz="0.0 0.0 0.0"/>
      <geometry>
        <cylinder length="0.05" radius="0.1"/>
      </geometry>
      <material name="wheel_material">
        <color rgba="0.0 0.0 0.0 1.0"/>
      </material>
    </visual>
    <collision>
      <origin rpy="1.570795 0.0 0.0" xyz="0.0 0.0 0.0"/>
      <geometry>
        <cylinder length="0.05" radius="0.1"/>
      </geometry>
    </collision>
    <inertial>
      <mass value="2"/>
      <inertia ixx="0.0038288160421875023" ixy="0.0" ixz="0.0" iyy="0.0038288160421875023" iyz="0" izz="0.007068583462500003"/>
      <origin rpy="1.570795 0.0 0.0" xyz="0.0 0.0 0.0"/>
    </inertial>
  </link>
  <!-- Right Wheel -->
  <link name="right_wheel_link">
    <visual>
      <origin rpy="1.570795 0.0 0.0" xyz="0.0 0.0 0.0"/>
      <geometry>
        <cylinder length="0.05" radius="0.1"/>
      </geometry>
      <material name="wheel_material">
        <color rgba="0.0 0.0 0.0 1.0"/>
      </material>
    </visual>
    <collision>
      <origin rpy="1.570795 0.0 0.0" xyz="0.0 0.0 0.0"/>
      <geometry>
        <cylinder length="0.05" radius="0.1"/>
      </geometry>
    </collision>
    <inertial>
      <mass value="2"/>
      <inertia ixx="0.0038288160421875023" ixy="0.0" ixz="0.0" iyy="0.0038288160421875023" iyz="0" izz="0.007068583462500003"/>
      <origin rpy="1.570795 0.0 0.0" xyz="0.0 0.0 0.0"/>
    </inertial>
  </link>
  <!-- Caster Wheel -->
  <link name="caster_link">
    <visual>
      <origin rpy="0.0 0.0 0.0" xyz="0.0 0.0 0.0"/>
      <geometry>
        <sphere radius="0.1"/>
      </geometry>
      <material name="caster_material">
        <color rgba="0.0 0.0 0.0 1.0"/>
      </material>
    </visual>
    <collision>
      <origin rpy="0.0 0.0 0.0" xyz="0.0 0.0 0.0"/>
      <geometry>
        <sphere radius="0.1"/>
      </geometry>
    </collision>
    <inertial>
      <mass value="0.5"/>
      <inertia ixx="1.6755160800000006e-06" ixy="0.0" ixz="0.0" iyy="1.6755160800000006e-06" iyz="0" izz="1.6755160800000006e-06"/>
      <origin rpy="0 0 0" xyz="0 0 0"/>
    </inertial>
  </link>
  <!-- LIDAR -->
  <link name="laser_frame">
    <visual>
      <origin rpy="0.0 0.0 0.0" xyz="0.0 0.0 0.0"/>
      <geometry>
        <cylinder length="0.05" radius="0.1"/>
      </geometry>
      <material name="wheel_material">
        <color rgba="1.0 0.0 0.0 0.0"/>
      </material>
    </visual>
    <collision>
      <origin rpy="0.0 0.0 0.0" xyz="0.0 0.0 0.0"/>
      <geometry>
        <cylinder length="0.05" radius="0.1"/>
      </geometry>
    </collision>
    <inertial>
      <mass value="2"/>
      <inertia ixx="0.0038288160421875023" ixy="0.0" ixz="0.0" iyy="0.0038288160421875023" iyz="0" izz="0.007068583462500003"/>
      <origin rpy="0.0 0.0 0.0" xyz="0.0 0.0 0.0"/>
    </inertial>
  </link>
  <!-- Joints -->
  <!-- Left Wheel Joint -->
  <joint name="left_wheel_joint" type="continuous">
    <origin rpy="0 0 0" xyz="-0.15 0.175 -0.05"/>
    <parent link="body_link"/>
    <child link="left_wheel_link"/>
    <axis xyz="0 1 0"/>
    <limit effort="100" velocity="10.0"/>
    <dynamics damping="0.1" friction="0.1"/>
  </joint>
  <!-- Right Wheel Joint -->
  <joint name="right_wheel_joint" type="continuous">
    <origin rpy="0 0 0" xyz="-0.15 -0.175 -0.05"/>
    <parent link="body_link"/>
    <child link="right_wheel_link"/>
    <axis xyz="0 1 0"/>
    <limit effort="100" velocity="10.0"/>
    <dynamics damping="0.1" friction="0.1"/>
  </joint>
  <!-- Caster Wheel Joint (fixed) -->
  <joint name="caster_joint" type="fixed">
    <origin rpy="0 0 0" xyz="0.15 0 -0.05"/>
    <parent link="body_link"/>
    <child link="caster_link"/>
  </joint>
  <!-- LIDAR -->
  <joint name="laser_joint" type="fixed">
    <parent link="body_link"/>
    <child link="laser_frame"/>
    <origin rpy="0 0 0" xyz="0.1 0 0.175"/>
  </joint>
  <!-- Gazebo Parameters -->
  <gazebo reference="body_link">
    <mu1>1.0</mu1>
    <mu2>1.0</mu2>
  </gazebo>
  <gazebo reference="right_wheel_link">
    <mu1>1.0</mu1>
    <mu2>1.0</mu2>
  </gazebo>
  <gazebo reference="left_wheel_link">
    <mu1>1.0</mu1>
    <mu2>1.0</mu2>
  </gazebo>
  <gazebo reference="caster_link">
    <mu1>0.000001</mu1>
    <mu2>0.000001</mu2>
  </gazebo>
  <gazebo reference="laser_frame">
    <sensor name="laser_frame" type="gpu_lidar">
      <pose>0 0 0 0 0 0</pose>
      <visualize>true</visualize>
      <update_rate>200</update_rate>
      <ray>
        <scan>
          <horizontal>
            <samples>360</samples>
            <resolution>1</resolution>
            <min_angle>-3.14</min_angle>
            <max_angle>3.14</max_angle>
          </horizontal>
        </scan>
        <range>
          <min>0.2</min>
          <max>10.0</max>
          <resolution>0.01</resolution>
        </range>
      </ray>
    </sensor>
  </gazebo>
  <!-- Gazebo Plugins -->
  <gazebo>
    <plugin filename="gz-sim-diff-drive-system" name="gz::sim::systems::DiffDrive">
      <right_joint>right_wheel_joint</right_joint>
      <left_joint>left_wheel_joint</left_joint>
      <wheel_separation>0.35</wheel_separation>
      <wheel_radius>0.1</wheel_radius>
      <max_linear_acceleration>10</max_linear_acceleration>
      <odom_publish_frequency>100</odom_publish_frequency>
      <topic>cmd_vel</topic>
      <odom_topic>odom</odom_topic>
      <odometry_frame>odom</odometry_frame>
      <robot_base_frame>base_link</robot_base_frame>
    </plugin>
    <plugin filename="gz-sim-joint-state-publisher-system" name="gz::sim::systems::JointStatePublisher">
      <topic>joint_states</topic>
      <joint_name>right_wheel_joint</joint_name>
      <joint_name>left_wheel_joint</joint_name>
    </plugin>
  </gazebo>
</robot>
